Workbook

Sheet Home
A1: =B3 &D4&B4& " Mapping Specification" -> AcctMod Mapping Specification | J1: Template Version | K1: 1.20171128
A3: Name of EFX Object: | B3: Acct | C3: Extended Object
A4: Operation: | B4: Mod | C4: Special Operation
A5: Channel:
A6: Object Version: | B6: 9.0.20251027
A8: =Information!B3 -> AcctService
A9: N/A
A11: =B3&D4&B4&"Oper" -> AcctModOper
A12: Update Account API modifies the account details, such as nickname and overdraft enrollment. This service allows updates to the following Share Account types: Checking Account (DDA), Savings Account (SDA) Money Market Account (MMA) or Individual Retirement Account (IRA).
A14: Conditions that trigger this implementation:
A15: None.
A16: Parameter Configuration in ESF Studio:
A17: List_BrandingValues_Portico
A18: Parameter Configuration in Service Provider:
A19: BrandingValues need to match
A20: Reference to other EFX related services:
A21: None.

Sheet Information
A1: =Home!B3 & Home!B4&" Mapping Information" -> AcctMod Mapping Information
A3: Service | B3: =Home!B3&"Service" -> AcctService
A4: Date | B4: 45994
A5: Organization | B5: Portico
A6: EFX Version | B6: 11 | C6: Version History
A7: Template version | B7: 12
B8: Name | D8: Represents | E8: Role | G8: Open Issues
A9: Team | B9: Linda Towns | D9: ESF | E9: BSA | G9: =Home!B3&Home!D4 -> Acct | H9: EFXHdr | I9: OvrdException | J9: Status
G10: =COUNTIF('EFX Object Mapping'!G3:G13, "X") -> 0 | H10: =COUNTIF('REST EFXHdr Mapping'!H10:H1498, "X") -> 0 | I10: =COUNTIF('OrvrdException Mapping'!G4:G1548, "X") -> 0 | J10: =COUNTIF('Status Mapping'!G3:G1550, "X") -> 0
G12: Business Rules | H12: Parameter
G13: =COUNTIF('Special Business Rules'!A3:A459, "X") -> 0 | H13: =COUNTIF('Parameter Configuration'!A3:A490, "X") -> 0
G15: =B5 & " Fields Implemented" -> Portico Fields Implemented
B16: =B3 & " Operations" -> AcctService Operations | D16: Messages | E16: EFX Object | G16: Request | H16: Response | I16: Total | J16: Status
B17: =Home!A11 -> AcctModOper | D17: =Home!B3&Home!D4&Home!B4&"Rq" -> AcctModRq | E17: =Home!B3 -> Acct | G17: =COUNTIFS('EFX Object Mapping'!A3:A2400,"X",'EFX Object Mapping'!S3:S2400,"X") -> 7 | H17: =COUNTIFS('EFX Object Mapping'!A3:A2400,"X",'EFX Object Mapping'!T3:T2400,"X") -> 1 | I17: =G17+H17 -> 8 | J17: Completed
D18: =Home!B3&Home!D4&Home!B4&"Rs" -> AcctModRs
B20: Service Provider Service | D20: Service Provider Operation | E20: Service Provider Message | F20: Version
B21: External Request Interface (ERI) web service | E21: ERI_EVENT_2100_RQ | F21: 6.0
E22: ERI_EVENT_2100_RS
B23: Self Service Interface | D23: Demographic Maintenance | E23: Demographic Maintenance Request | F23: 6.0
E24: Demographic Maintenance Response
B30: Template Filters
B31: AcctSummInfo
B32: SvcIdent
B33: AcctKeys/CurCode
B34: PersonPartyListinfo
B35: OrgPartyListInfo
B36: PostAddr/TimeFrame/RecurRule/

Sheet Version History
A1: Version History
A2: Date | B2: Tab | C2: Schema Version | D2: Patch # | E2: Revision | F2: Release Notes | G2: Created By | H2: JIRA# / CR# | I2: Release Doc Impact | J2: Development Impact | K2: DevPortal Impact | L2: From Release
A3: 45975 | B3: EFX Object Mapping, Status Mapping, OvrdException Mapping | C3: 9.0.20251027 | D3: 0 | E3: Macro Function: New mapping sheet schema version 9.0.20251027 | F3: We added the following API endpoints to modify account details for Share Accounts such as Checking Account (DDA), Savings Account (SDA) Money Market Account (MMA) or Individual Retirement Account (IRA). - Update Account -DDA_SDA_INET | G3: Linda Towns | H3: FETP-16646/ FETP-18165 | I3: Yes | J3: Yes | K3: Yes | L3: R2025.4

Sheet EFX Object Mapping
A1: Implemented | B1: AcctMod Schema | G1: Open Issue | H1: Service Provider Schema | S1: AcctModRq | T1: AcctModRs | U1: Blueprint | V1: PCI/PII Data Fields
B2: XPATH | C2: Description | D2: Usage | E2: DataType | F2: Allowed Values | H2: EFX Allowed Values | I2: Service Provider Implementation Notes | J2: Published Description | K2: XPATH | L2: Usage | M2: DataType | N2: Allowed Values | O2: Transformation Rules | P2: Default Value | Q2: List Table | R2: Design Notes
A3: X | B3: Status | C3: This aggregate is used in all response messages to indicate the results of the message. | D3: Optional | E3: Aggregate | T3: X
B4: OvrdAutoAckInd | C4: Override Auto Acknowledgement indicates if exceptions should be auto-acknowledged by the system. If the value is set to False, or the element is omitted in the request message, all exceptions will be returned in the Status aggregate of the response message. These can then be manually acknowledged in a resubmission of the original request message in the OverrideExceptionData aggregate. If the value is set to True, then any exceptions that can be overridden will be automatically acknowledged by the system and only exceptions that cannot be overridden will be returned in the Status aggregate of the response message. | D4: Optional Choice | E4: Boolean | F4: true false | S4: X | Z4: X
B5: OvrdExceptionData | C5: This aggregate is used for Add/Mod/Del/Rev request messages to indicate message exceptions that are to be overridden. | D5: Optional | E5: Aggregate
B6: RecCtrlIn | C6: Record Control In. Allows the client to specify a maximum number of records that it is capable of processing within a single response. | D6: Optional | E6: Aggregate
B7: RecCtrlIn/MaxRecLimit | C7: Maximum Record Limit. This is the maximum number of records that the server should add to the result set which is available to satisfy this request. | D7: Optional | E7: Long
B8: RecCtrlIn/Cursor | C8: Cursor. Next Record Pointer Included in the response only if additional records are available. | D8: Optional | E8: C-250
B9: RecCtrlOut | C9: Record Control Out. Used in inquiry responses to provide a client that used the RecCtrlIn aggregate in the request with information it needs to retrieve the rest of the records that matched the specified selection criteria. | D9: Optional | E9: Aggregate
B10: RecCtrlOut/SentRecCount | C10: Sent Record Count. Number of records matching the selection criteria that are included in this message. | D10: Required | E10: Long
B11: RecCtrlOut/MatchedRecCount | C11: Matched Record Count Total number of records matching the selection criteria.. | D11: Optional | E11: Long
B12: RecCtrlOut/RemainRecCount | C12: Remain Record Count. Total number of records matching the selection criteria that have not been sent yet. | D12: Optional | E12: Long
A13: X | B13: AcctKeys | C13: Account Identifier. Uniquely identifies an account held at a financial institution. | D13: Required | E13: Aggregate | O13: If AcctKeys not provided, see exception 1 design notes | R13: Exception 1 HTTP 400-Bad Request "Status": { "StatusCode": "1020", "StatusDesc": "Required Element Not Included", "Severity": "Error", "SvcProviderName": "ESF", "ServerStatusDesc": "Account keys is required" } | S13: X | U13: X | Z13: X
A14: X | B14: AcctKeys/AcctId | C14: Account Identifier. Uniquely identifies an account held at a financial institution. | D14: Required | E14: NC-36 | I14: For Portico, this field is concatenation of MemberNumber, AcctType and AcctId Format: MemberNumberAcctTypeAcctId AcctType for DDA, SDA, MMA, IRA = 'S' Example: 123456789012S12 | K14: Account Id #1/ Account Id M0MBRNBR/ Member Number | L14: Required Required | M14: string(38) String (12) | O14: EFX Exception Handeling: If AcctId field is not present in request Then see the design notes- Exception 1 for error handling Inspect AcctKeys/AcctId (AcctId) If "S" is not present Then see the design notes- Exception 2 for error handling For Account Id #1/ Account Id: Move AcctKeys/AcctId (Member Number) ==> Account Id #1/ Account Id (starting in position 1, up to 12) Replace first 'S' (AcctType) with '=' Move AcctKeys/AcctId (AcctId) --> after '=' Move "bbbbbbbbbbbbbbbbbbbbbb" --> to remaining positions (up to 38) For M0MBRNBR/ Member Number: Move AcctKeys/AcctId (Member Number) ==> M0MBRNBR/ Member Number (without spaces) If invalid value see design notes -Portico returns Exception 3 | R14: This field is concatenation of: MemberNumber (12 bytes) AcctType - S(Share) (1 byte) AcctId - share at Portico (2 bytes - numeric) AcctSel/AcctKeys/AcctId format: (MemberNumber-AcctType-Acctid) Ex: 123456789012S75 Exception 1 If the AcctId is not provided, eg: "AcctId":" ", (this is for any number of blanks) HTTP 400 - Bad Request { "Status": { "StatusCode": "1020", "StatusDesc": "Required Element Not Included", "Severity": "Error", "SvcProviderName": "ESF" "ServerStatusDesc": "Account identifier is required" } } Exception 2: Validate AcctId has 'S', if error: HTTP 400 - Bad Request { "Status": { "StatusCode": "1090", "StatusDesc": "Invalid Value", "Severity": "Error", "SvcProviderName": "ESF" "ServerStatusDesc": "Invalid account identifier" } } If the PartyId not present in Portico Exception 3 (see Portico Status Code Mapping) HTTP 404 - Not Found "Status": { "StatusCode": "1121", "StatusDesc": "No Records Found", "Severity": "Error", "SvcProviderName": "Portico", "ServerStatusCode": "Portico provides" ServerStatusDesc: "Party identifier not found" } } | S14: X | U14: X | V14: X | Z14: X
B15: AcctKeys/SubAcctId | C15: Sub Account Identifier. Also used as CostCenter for GLA Accounts. | D15: Optional | E15: NC-36 | S15: X | Z15: X
A16: X | B16: AcctKeys/AcctType | C16: Account Type. | D16: Optional | E16: ExtendedEnum | F16: CCA RRA LEAS CDA MLN CLA CRD DDA EQU GLA ILA AdultCashISA IRA RET EXT JuniorCashISA LIP LOAN LOC CLOC MLA PBA PORT SDA SDB MMA DDL | H16: DDA SDA MMA IRA | I16: DDA - Checking Account SDA - Savings Account MMA - Money Market Account IRA - Individual Retirement Account | K16: See Transformation Rules. | O16: EFX Exception Handeling: If AcctType field not present in request or not (DDA,SDA, MMA, IRA) or If AcctType field = (DDA, SDA, MMA, IRA) and AcctKeys/AcctId not = "S" Then see the design notes- Exception1 for error handling | Q16: List_AcctType_Portico_INET | R16: AcctType not in Allowed Values (or not sent): Exception 1: HTTP 400 - Bad Request { "Status": { "StatusCode": "1090", "StatusDesc": "Invalid Value", "Severity": "Error", "SvcProviderName": "ESF" "ServerStatusDesc": "Invalid account type" } } | S16: X | Z16: X
B17: AcctKeys/CardKeys | C17: Card Keys. Used to identify the Card record. | D17: Required Choice | E17: Aggregate | S17: X | Z17: X
B18: AcctKeys/CardKeys/ISOCode | C18: ISO Code. | D18: Optional | E18: OpenEnum | S18: X | Z18: X
B19: AcctKeys/CardKeys/CardNum | C19: Card Number. | D19: Required Choice | E19: NC-32 | S19: X | Z19: X
B20: AcctKeys/CardKeys/CardId | C20: Card Identifier. | D20: Required Choice | E20: NC-36 | S20: X | Z20: X
B21: AcctKeys/CardKeys/CardSeqNum | C21: Card Sequence Number. | D21: Optional | E21: NC-3 | S21: X | Z21: X
B22: AcctKeys/CardKeys/CardIdent | C22: Card Identifier. | D22: Optional Choice | E22: Aggregate | S22: X | Z22: X
B23: AcctKeys/CardKeys/CardIdent/CardIdentType | C23: Card Identification Type. Valid values include: PORT | D23: Optional | E23: ExtendedEnum | F23: PORT | S23: X | Z23: X
B24: AcctKeys/CardKeys/CardIdent/CardIdentValue | C24: Card Identification Value. | D24: Optional | E24: NC-36 | S24: X | Z24: X
B25: AcctKeys/AcctIdent | C25: Account Identifier. Other account identifiers used as part of the account object key. | D25: Required Choice | E25: Aggregate | S25: X | Z25: X
B26: AcctKeys/AcctIdent/AcctIdentType | C26: Account Identification Type. Valid values include: AcctNum, Port, AcctTypeCode. | D26: Optional | E26: ExtendedEnum | F26: AcctNum PORT AccessId PartyId AliasAcct AcctTypeCode CLOC DraftId DraftId2 ACHId | S26: X | Z26: X
B27: AcctKeys/AcctIdent/AcctIdentValue | C27: Account Identification Value. | D27: Optional | E27: NC-36 | S27: X | Z27: X
B28: AcctKeys/FIIdentType | C28: Financial Institution Identification Type. | D28: Optional | E28: ExtendedEnum | F28: ABA RoutingNum | S28: X | Z28: X
B29: AcctKeys/FIIdent | C29: Financial Institution Identification. | D29: Optional | E29: NC-34 | S29: X | Z29: X
B30: AcctKeys/BranchIdent | C30: Branch Identifier. | D30: Optional | E30: NC-22 | S30: X | Z30: X
B31: DepositAcctInfo | C31: Deposit Account Information. The DepositAcctInfo aggregate contains the details of a Deposit Account. | D31: Required Choice | E31: Aggregate | S31: X | Z31: X
B32: DepositAcctInfo/Brand | C32: Brand. | D32: Optional | E32: OpenEnum | S32: X | Z32: X
B33: DepositAcctInfo/GoodThruDt | C33: Good Thru Date. Indicates the current processing date of the system. | D33: Optional | E33: Date | S33: X | Z33: X
B34: DepositAcctInfo/AcctDtlStatus | C34: Account Detail Status. Indicates the current status of the account. | D34: Optional | E34: ExtendedEnum | F34: Active Open ActiveNoRenew ActivePendingUpdate Approved Assumed AuthProhibited Bankruptcy BankUse ChargedOff ClientControlled Closed ClosedReopenDeposit ClosedToAdvances ClosedToday ClosedToPosting ClosedWithBalances Collection CoolingOff Decease Delinquent Denied Dormant Drill EarlyCollection Escheated Foreclosure Frozen Hold HotCard Inactive InitialClose Lost Matured New NewThisMonth NoCreditPost NoDebitPost NonAccrual NoWithdrawal Originating Other PastDue PendingClosed Probate Purge Rented Repossession Revoked Surrendered TransferredOut Unusable Vacant Void | S34: X | Z34: X
B35: DepositAcctInfo/AcctDtlStatusEnumDesc | C35: Account Detail Status Enumeration Description. | D35: Optional | E35: C-80 | S35: X | Z35: X
B36: DepositAcctInfo/AcctDtlStatusDt | C36: Account Detail Status Date. Indicates the date of the current status of the account. | D36: Optional | E36: Date | S36: X | Z36: X
B37: DepositAcctInfo/IsActiveInd | C37: Is Active Indicator. Indicate the account is active. | D37: Optional | E37: Boolean | F37: true false | S37: X | Z37: X
B38: DepositAcctInfo/FederalInsuranceEligibility | C38: Federal Insurance Eligibility. | D38: Optional | E38: ClosedEnum | F38: Eligible NotEligible NotApplicable | S38: X | Z38: X
B39: DepositAcctInfo/CurCode | C39: Account Currency Code. The currency Code of the account is different from the account preference. | D39: Optional | E39: Aggregate | S39: X | Z39: X
B40: DepositAcctInfo/CurCode/CurCodeType | C40: Currency Code Type. | D40: Optional | E40: ClosedEnum | F40: ISO4217-Alpha ISO4217-Numeric | S40: X | Z40: X
...

Sheet REST EFXHdr Mapping
A1: Implemented | H1: Open Issues | I1: Service Provider Schema
B2: XPATH | C2: Description | D2: Published Description | E2: Usage | F2: DataType | G2: Allowed Values | I2: EFX Allowed Values | J2: Service Provider Implementation Notes | K2: XPATH | L2: Usage | M2: DataType | N2: Allowed Values | O2: Transformation Rules | P2: Default Value | Q2: List Table | R2: Notes
A3: X | B3: OrganizationId | C3: Organization Identifier is a unique identifier that represents the financial institution or holding company. This identifier does not necessarily match the organization identifier or bank identifier in the backend system. To ensure uniqueness across all institutions in all parts of the world, use the Dun & Bradstreet number. | D3: Unique identifier to represent the financial institution or holding company. | E3: Required | F3: C-36
A4: x | B4: TrnId | C4: Transaction UUID (Universal Unique Identifier) of the current message. | D4: Transaction UUID (Universal Unique Identifier) of the current message. | E4: Optional | F4: C-36
A5: x | B5: VendorId | C5: Unique vendor identification number provided by Fiserv to identify the vendor. | D5: Fiserv provided unique vendor identification number. | E5: Optional | F5: C-255
B6: ClientRequestId | C6: Unique UUID (Universal Unique Identifier) generated by the client that is used for enforcing idempotence on POST actions. | D6: Unique UUID (Universal Unique Identifier) generated by the client that is used for enforcing idempotence on POST actions. | E6: Optional | F6: C-36
B7: MultiSystemInd | C7: For internal use only . Multi-System Service (MSS) feature is enabled. | E7: Optional | F7: Boolean
B8: SvcNbr | C8: For organizations processing the Multi-System Service feature (MSS), this identifies the Service Provider (account processor). | D8: For organizations processing the Multi-System Service feature (MSS), this identifies the Service Provider (account processor). | E8: Optional | F8: NC-36
A9: x | B9: Context | C9: The context aggregate defines additional information related to the specific channels. | D9: Additional information related to the specific channels. | E9: Optional | F9: Aggregate
A10: x | B10: Context/ClientAppName | C10: Name of the client application that is used to send the service request, such as Architect, Commercial Center and others. | D10: Name of the client application that is used to send the service request, such as Architect, Commercial Center and others. | E10: Optional | F10: C-40
A11: x | B11: Context/Channel | C11: Name of the channel used by the client application. | D11: Name of channel used by the client application, such as Online, Branch, Phone, EFT and Teller. | E11: Optional | F11: ExtendedEnum | G11: Online Branch Phone EFT Teller
A12: x | B12: Context/ClientDateTime | C12: Client date and time as reported by the client application that is making the service request. | D12: Client date and time as reported by the client application while sending the service request. EFX Date format: YYYY-MM-DD Example: 2021-12-31 | E12: Optional | F12: DateTime
B13: Context/isOverridden | C13: Indicates whether previous exception is being overridden by the sender . | D13: Indicates whether previous exception is being overridden by the sender . | E13: Optional | F13: Boolean
B14: Context/TrnIdent | C14: Unique identification value of transaction defined by the client. Also known as Trace Number or Sequence in some systems. When used by a Network defined transaction the value of this identifier is typically set to NC-12. | D14: Client-defined unique identification value of transaction. Also known as TraceNumber or Sequence in some systems. When used by a Network defined transaction, the value of this identifier is typically set to narrow character of 12. | E14: Optional | F14: C-36
B15: Context/ClientTerminalSeqNum | C15: Client Terminal Sequence Number. | D15: Client Terminal Sequence Number. | E15: Optional | F15: C-36
B16: Context/OriginatorType | C16: The type of organization that the originator represents. This is usually a coded value representing the industry that the organization operates in. It contains the SIC code. For ISO 8583 (DE18) the element is restricted to NC-4. Originator Type codes that apply to financial institutions are: • 6010 - Financial institution—bank, savings and loan (S&L), or credit union • 6011 - Financial institution—ATM • 6012 - Financial institution—merchandise sale • 6999 - Financial institution—home banking | D16: Type of the organization industry that the originator represents. This is usually a coded value representing the industry that the organization operates in. It contains the SIC code. For ISO 8583 (DE18) the element is restricted to 4 narrow characters. Valid values are: 6010 (Financial institution - bank, savings and loan (S and L), or credit union) 6011 (Financial institution - ATM) 6012 (Financial institution - merchandise sale) 6999 (Financial institution - home banking) | E16: Optional | F16: Long
B17: Context/TerminalIdent | C17: Unique code identifying a terminal at the card acceptor location (such as terminal code or terminal number of ATM). See For ISO 8583 (DE41) the lement is restricted to a narrow character with maximum length of 8. | D17: Unique code to identify a terminal at the card acceptor location, such as terminal code or terminal number of ATM. For ISO 8583 (DE41) the element is restricted to a narrow character with maximum length of 8. | E17: Optional | F17: C-36
B18: Context/TerminalAddr1 | C18: Terminal address line 1. | D18: Terminal address line 1. | E18: Optional | F18: C-64
B19: Context/TerminalAddr2 | C19: Terminal address line 2. | D19: Terminal address line 2. | E19: Optional | F19: C-64
B20: Context/TerminalAddr3 | C20: Terminal address line 3. | D20: Terminal address line 3. | E20: Optional | F20: C-64
B21: Context/TerminalAddr4 | C21: Terminal address line 4. | D21: Terminal address line 4. | E21: Optional | F21: C-64
B22: Context/TerminalCity | C22: Terminal city name. | D22: Name of the city where the terminal is located. | E22: Optional | F22: C-40
B23: Context/TerminalCounty | C23: Terminal county name. | D23: Name of the county where the terminal is located. | E23: Optional | F23: C-40
B24: Context/TerminalStateProv | C24: State province value as per ISO 3166-2:US codes where the terminal is located. | D24: State province value as per ISO 3166-2:US (Hiperlink to https://en.wikipedia.org/wiki/ISO_3166-2:US) codes where the terminal is located. | E24: Optional | F24: C-32
B25: Context/TerminalPostalCode | C25: Postal Code where the terminal is located. | D25: Postal code where the terminal is located. | E25: Optional | F25: C-11
B26: Context/TerminalCountryCodeSource | C26: Standard country code format where the terminal is located. | D26: Standard country code format where the terminal is located. Valid values are: ISO3166-Numeric (Hiperlink to: https://en.wikipedia.org/wiki/ISO_3166-1_numeric) ISO3166-Alpha-3 (Hiperlink to: https://en.wikipedia.org/wiki/ISO_3166-1_alpha-3) | E26: Optional | F26: ClosedEnum | G26: ISO3166-Numeric ISO3166-Alpha-3
B27: Context/TerminalCountryCodeValue | C27: Country code value as per the ISO source code set in the TerminalCountryCodeSource field. | D27: Country code value as per the ISO source code set in the TerminalCountryCodeSource field. For example, if the country code format is set to ISO3166-Alpha-3, then the country code value for the United States would be USA. | E27: Optional | F27: C-80
B28: Context/PhoneType | C28: Type of a phone. | D28: Type of a phone. Valid values are: EvePhone DayPhone EveFax DayFax Home Work Mobile Fax Pager Modem Other | E28: Optional | F28: ExtendedEnum | G28: EvePhone DayPhone EveFax DayFax Home Work Mobile Fax Pager Modem Other
B29: Context/PhoneNum | C29: Phone number. | D29: Phone number. | E29: Optional | F29: C
B30: Context/PhoneExchange | C30: Phone exchange. | D30: Phone exchange. | E30: Optional | F30: C-80
B31: Context/TerminalOwnerName | C31: Name of the owner or operator of the terminal. For ISO 8583 (DE43) the element is restricted to C-15. | D31: Name of the owner or operator of the terminal. For ISO 8583 (DE43) the element is restricted to C-15 characters. | E31: Optional | F31: C-40
B32: Context/SystTraceAuditNum | C32: Number assigned by the transaction originator to assist in identifying a transaction uniquely. The trace number remains unchanged for all messages throughout the life of a transaction. This number is not a terminal receipt number. The originating processor increments the trace number by one for each transaction sent to the switch. For ISO 8583 (DE11) the element is restricted to NC-6 | D32: Unique trace number assigned by the transaction originator to identify the transaction. The trace number remains unchanged for all messages throughout the life of a transaction. The originating processor increments the trace number by one for each transaction sent to the switch. For ISO 8583 (DE11) the element is restricted to 6 narrow characters. | E32: Optional | F32: C-36
B33: Context/NetworkIdent | C33: Identifies the interchange network for the transaction. The transaction is applied to the specified network settlement counts and balances. For ISO 8583 (DE62) the element is restricted to NC-6 | D33: Identifier of the interchange network for the transaction. The transaction is applied to the specified network settlement counts and balances. For ISO 8583 (DE62) the element is restricted to 6 narrow characters. | E33: Optional | F33: C-80
B34: Context/NetworkRefIdent | C34: Document reference supplied by the system retaining the original source document and used to assist in locating that document. The acquirer of a transaction assigns this number. The issuer processor must retain it in the event that a chargeback is submitted for the transaction. For ISO 8583 (DE37) the element is restricted to C-12 | D34: Document reference supplied by the system retaining the original source document and used to assist in locating that document. The acquirer of a transaction assigns this number. The issuer processor must retain it in the event that a chargeback is submitted for the transaction. For ISO 8583 (DE37) the element is restricted to 12 characters. | E34: Optional | F34: C-36
B35: Context/AcquirerIdent | C35: Identifier of the acquirer who processes the financial transaction. It is a mandatory element in all authorization and financial messages and does not change throughout the life of a transaction. EPOC considers the acquirer as the terminal owner for reporting purposes. For ISO 8583 (DE32) the element is restricted to C-12 | D35: Identifier of the acquirer who processes the transaction. EPOC considers the acquirer as the terminal owner for reporting purposes. For ISO 8583 (DE32) the element is restricted to 12 characters. | E35: Optional | F35: C-36
B36: Context/AcquirerCountryCodeSource | C36: Standard country code format where the acquirer is located. | D36: Standard country code format where the acquirer is located. Valid values are: ISO3166-Numeric (Hiperlink to: https://en.wikipedia.org/wiki/ISO_3166-1_numeric) ISO3166-Alpha-3 (Hiperlink to: https://en.wikipedia.org/wiki/ISO_3166-1_alpha-3) | E36: Optional | F36: ClosedEnum | G36: ISO3166-Numeric ISO3166-Alpha-3
B37: Context/AcquirerCountryCodeValue | C37: Country code value of Acquirer as per the ISO source code set in the AcquirerCountryCodeSource field. | D37: Country code value of Acquirer as per the ISO source code set in the AcquirerCountryCodeSource field. For example, if the country code format is set to ISO3166-Alpha-3, then the country code value for the United States would be USA. | E37: Optional | F37: C-80
B38: Context/MerchNum | C38: Unique identification number of a merchant. For ISO 8583 (DE42) the element is restricted to C-15 | D38: Unique identification number of a merchant. For ISO 8583 (DE42) the element is restricted to 15 characters. | E38: Optional | F38: C-23
B39: Context/SettlementDate | C39: Transaction settlement date. Used by ISO 8583 (DE63). | D39: Date on which the transaction is settled. Used by ISO 8583 (DE63). EFX Date format: YYYY-MM-DD Example: 2021-12-31 | E39: Optional | F39: Date
B40: Context/SettlementIdent | C40: Identification of the settlement account in which the transaction will be settled. | D40: Identifier of the settlement account in which the transaction is to be settled. | E40: Optional | F40: C-36
...

Sheet Status Mapping
A1: Implemented | B1: Status Schema | G1: Open Issues | H1: Service Provider Schema
B2: XPATH | C2: Description | D2: Usage | E2: DataType | F2: Allowed Values | H2: EFX Allowed Values | I2: Service Provider Implementation Notes | J2: XPATH | K2: Usage | L2: DataType | M2: Allowed Values | N2: Transformation Rules | O2: Notes
A3: X | B3: Status | C3: Status. | D3: Required | E3: Aggregate | Z3: X
A4: X | B4: Status/StatusCode | C4: Status Code is used to indicate the EFX Standard Status Codes that identify the result of the operation. | D4: Required | E4: C-20 | Z4: X
A5: X | B5: Status/StatusDesc | C5: Status Description is the explanatory EFX standard text associated with the EFX StatusCode. | D5: Required | E5: C-255 | Z5: X
A6: X | B6: Status/Severity | C6: Severity is the standard EFX severity associated with the EFX StatusCode. | D6: Required | E6: ClosedEnum | F6: Error Warning Info | H6: Error Warning Info | Z6: X
A7: X | B7: Status/ServerStatusCode | C7: Server Status Code is used to indicate the service provider’s application status code that tells the consumer the result of the operation call. | D7: Optional | E7: C-20 | Z7: X
A8: X | B8: Status/ServerStatusDesc | C8: Server Status Description is the service provider’s explanatory text associated with the ServerStatusCode. | D8: Optional | E8: C-255 | Z8: X
A9: X | B9: Status/SvcProviderName | C9: Service Provider Name is a globally unique identifier for a service provider which indicates the location of the service provider that gave the error. | D9: Required | E9: URL | Z9: X | AA9: =IF(S9="X",IF(A9="X",2,1),0) -> 0 | AB9: =IF(T9="X",IF(A9="X",2,1),0) -> 0 | AC9: =IF(U9="X",IF(A9="X",2,1),0) -> 0 | AD9: =IF(V9="X",IF(A9="X",2,1),0) -> 0 | AE9: =IF(W9="X",IF(A9="X",2,1),0) -> 0 | AF9: =IF(X9="X",IF(A9="X",2,1),0) -> 0 | AG9: =IF(Y9="X",IF(A9="X",2,1),0) -> 0
A10: x | B10: Status/OvrdExceptionInd | C10: Override Exception Indicator indicates whether the exception can be overridden by resubmitting the request message. | D10: Optional | E10: Boolean | F10: true false | Z10: X
B11: Status/SubjectRole | C11: Indicates the authorization level required for override. | D11: Optional | E11: ExtendedEnum | F11: Teller Supervisor | Z11: X
A12: x | B12: Status/SubjectElement | C12: Subject Element aggregate provides information about which elements caused the resulting status code. The aggregate is repeating to allow for a relationship between one or more elements if the combination caused the resulting status code. | D12: Optional Repeating | E12: Aggregate | Z12: X
A13: x | B13: Status/SubjectElement/Path | C13: For messages that have been standardized across Fiserv, the Path indicates which EFX element is in error. It provides either the path of the element, or just the element name. If it provides the path, it must use the XPath absolute notation with the starting node being the node of the message, and ending with the name of the element in error. | D13: Optional | E13: XPath | Z13: X
A14: x | B14: Status/SubjectElement/Value | C14: Value is the string representation of the EFX data value of the element in error. This field is intended to provide a human readable visual hint as to the value in error. It should not be provided for fields that cannot be represented as a string (i.e. binary data). | D14: Optional | E14: C-256 | Z14: X
B15: Status/SubjectElement/ServerPath | C15: Server Path is the service provider’s identification of the field in their schema, such as an XPath, field ID, or field name that is associated with the ServerStatusCode. If this element is set, it must be returned in the ServerPath element of the OvrdExceptionData aggregate if the exception is being overridden | D15: Optional | E15: C-256 | Z15: X
B16: Status/ContentHTML | C16: Used to provide HTML context in some status responses. For example in Premier, upon failure an HTML page is provided to support the maintenance of failures reported. The Content HTML may be availalble for a time interval which is established by the service provider. | D16: Optional | E16: C | Z16: X
A17: X | B17: Status/AdditionalStatus | C17: Additional Status aggregate may appear once for each additional status that the server intends to provide. | D17: Optional Repeating | E17: Aggregate | Z17: X
A18: X | B18: Status/AdditionalStatus/StatusCode | C18: Status Code is used to indicate the EFX Standard Status Codes that identify the result of the operation. | D18: Required | E18: C-20 | Z18: X
A19: X | B19: Status/AdditionalStatus/StatusDesc | C19: Status Description is the explanatory EFX standard text associated with the EFX StatusCode. | D19: Required | E19: C-255 | Z19: X
A20: X | B20: Status/AdditionalStatus/Severity | C20: Severity is the standard EFX severity associated with the EFX StatusCode. | D20: Required | E20: ClosedEnum | F20: Error Warning Info | H20: Error Warning Info | Z20: X
A21: X | B21: Status/AdditionalStatus/ServerStatusCode | C21: Server Status Code is used to indicate the service provider’s application status code that tells the consumer the result of the operation call. | D21: Optional | E21: C-20 | Z21: X
A22: X | B22: Status/AdditionalStatus/ServerStatusDesc | C22: Server Status Description is the service provider’s explanatory text associated with the ServerStatusCode. | D22: Optional | E22: C-255 | Z22: X
A23: X | B23: Status/AdditionalStatus/SvcProviderName | C23: Service Provider Name is a globally unique identifier for a service provider which indicates the location of the service provider that gave the error. | D23: Required | E23: URL | Z23: X | AA23: =IF(S23="X",IF(A23="X",2,1),0) -> 0 | AB23: =IF(T23="X",IF(A23="X",2,1),0) -> 0 | AC23: =IF(U23="X",IF(A23="X",2,1),0) -> 0 | AD23: =IF(V23="X",IF(A23="X",2,1),0) -> 0 | AE23: =IF(W23="X",IF(A23="X",2,1),0) -> 0 | AF23: =IF(X23="X",IF(A23="X",2,1),0) -> 0 | AG23: =IF(Y23="X",IF(A23="X",2,1),0) -> 0
A24: x | B24: Status/AdditionalStatus/OvrdExceptionInd | C24: Override Exception Indicator indicates whether the exception can be overridden by resubmitting the request message. | D24: Optional | E24: Boolean | F24: true false | Z24: X
A25: x | B25: Status/AdditionalStatus/SubjectElement | C25: Subject Element aggregate provides information about which elements caused the resulting status code. The aggregate is repeating to allow for a relationship between one or more elements if the combination caused the resulting status code. | D25: Optional Repeating | E25: Aggregate | Z25: X
A26: x | B26: Status/AdditionalStatus/SubjectElement/Path | C26: For messages that have been standardized across Fiserv, the Path indicates which EFX element is in error. It provides either the path of the element, or just the element name. If it provides the path, it must use the XPath absolute notation with the starting node being the node of the message, and ending with the name of the element in error. | D26: Optional | E26: XPath | Z26: X
A27: x | B27: Status/AdditionalStatus/SubjectElement/Value | C27: Value is the string representation of the EFX data value of the element in error. This field is intended to provide a human readable visual hint as to the value in error. It should not be provided for fields that cannot be represented as a string (i.e. binary data). | D27: Optional | E27: C-256 | Z27: X
B28: Status/AdditionalStatus/SubjectElement/ServerPath | C28: Server Path is the service provider’s identification of the field in their schema, such as an XPath, field ID, or field name that is associated with the ServerStatusCode. If this element is set, it must be returned in the ServerPath element of the OvrdExceptionData aggregate if the exception is being overridden | D28: Optional | E28: C-256 | Z28: X

Sheet OrvrdException Mapping
B1: OvrdAutoAckInd | C1: Override Autoacknowledgment. Used when the midleware is in charge of auto-acknowledgement of exceptions. | D1: Optional Choice | E1: Boolean | F1: true false | G1: A | Z1: X
A2: Implemented | B2: EFX Schema | G2: Open Issues | H2: Service Provider Schema
B3: XPATH | C3: Description | D3: Usage | E3: DataType | F3: Allowed Values | H3: EFX Allowed Values | I3: Service Provider Implementation Notes | J3: XPATH | K3: Usage | L3: DataType | M3: Allowed Values | N3: Transformation Rules | O3: Default Value | P3: Notes
B4: OvrdExceptionData | C4: Override Exception Data Type is used to indicate the exceptions being manually acknowledged by the client. | D4: Optional Choice | E4: Aggregate | Z4: X
B5: OvrdExceptionData/OverrideException | C5: This aggregate is used to identify the exception to override | D5: Optional Repeating | E5: Aggregate | Z5: X
B6: OvrdExceptionData/OverrideException/SubjectIdent | C6: Subject Identification Identifies the subject who is overriding this exception. | D6: Optional | E6: NC-36 | Z6: X
B7: OvrdExceptionData/OverrideException/SubjectRole | C7: Subject Role identifies the role of who is overriding the exception. | D7: Optional | E7: ExtendedEnum | F7: Teller Supervisor | Z7: X
B8: OvrdExceptionData/OverrideException/OvrdExceptionCode | C8: Identifies an exception code that is to be overridden. This would be the ServerStatusCode from the Message Status section, | D8: Optional | E8: C-40 | G8: C | Z8: X
B9: OvrdExceptionData/OverrideException/OvrdElement | C9: This aggregate is used for Information about the element that corresponds to the override exception code. | D9: Optional | E9: Aggregate | Z9: X
B10: OvrdExceptionData/OverrideException/OvrdElement/Path | C10: Path is used to indicate the EFX element XPath to be overridden. It provides the path of the element using the XPath absolute notation with the starting node being the node of the message, and ending with the name of the element in error. | D10: Optional | E10: XPath | Z10: X
B11: OvrdExceptionData/OverrideException/OvrdElement/Value | C11: Value is a string representation of the EFX data value of the element that is to be overridden. | D11: Optional | E11: C-256 | Z11: X
B12: OvrdExceptionData/OverrideException/OvrdElement/ServerPath | C12: Server Path is the Service Provider’s identification of the field in their schema, such as an XPath, field ID, or field name that is to be overridden. This element is required if the ServerPath was set in the SubjectElement aggregate of the Message Status section | D12: Optional | E12: C-256 | Z12: X

Sheet ESF Validation Rules
A1: ESF Schema Validation Rules | B1: Condition | C1: StatusCode | D1: Severity | E1: StatusDesc

Sheet Special Business Rules
A1: Open Issue | B1: Service Provider Schema
B2: Xpath | C2: Usage | D2: DataType | E2: Allowed Values | F2: Rule Details | G2: Value
B3: Request Parameters
B4: Message Type Identifier() | C4: 4 | D4: Numeric | E4: Required at Portico | F4: 0100(Inquiries) | G4: 0100
B5: Bit Map Mask | C5: 8 | D5: AlphaNumeric | F5: SSI600bb | G5: SSI600bb
B6: PAN | C6: 30 | D6: AlphaNumeric | F6: Combination - consists of Length, Institution & Account fields. Identifies Financial Institution (The Primary Account Number (PAN) field is primarily used to identify the institution). Value that is setup at Fromtend . Length is "30" . Ex. 190004223329999999999(Digits occupy 19 of the PAN number and then remainning will be spaces). PAN Institution Identifier(which will identify the institution and unique per institution and PAN Account always will be 9999999999 | G6: See List_BrandingValues_Portico for PAN | H6: 190004223329999999999bbbbbbbbb
B7: PAN - length | C7: 2 | D7: Numeric | F7: Length of Institution & Account fields (valid values 11 - 19)
B8: PAN - Institution | C8: Variable | D8: Numeric | E8: [Branded Value] | F8: Route/Transit, ISO, BIN or other institutional identifier (valid length 1 - 9) | H8: 422332
B9: PAN - Account | C9: 10 | D9: Numeric | F9: Set value to 9's (9999999999) | H9: 9999999999
B10: Space filler | C10: Variable | D10: AlphaNumeric | F10: Space fill remaining digits of the 30 characters of the PAN (valid length 9 -17)
B11: Process Code | C11: 6 | D11: AlphaNumeric | E11: Required at Portico | G11: DM0000
B12: Transaction Amount | C12: 11 | D12: Numeric | F12: constant value : 00000000000 | G12: 00000000000
B13: System Trace Number | C13: 6 | D13: Numeric | F13: Portico doesn't use but stores field - can be used for tracking (increase number by 1 - User generated) Ex.999999 | G13: HHMMSS
B14: Acquiring Institution Id | F14: Combination of Two Zeroes and Self Service Unit Id | G14: 00888888888
B15: Acquiring Institution Id - Two Zeroes | C15: 2 | D15: Numeric | F15: 00
B16: Acquiring Institution Id- Self Service Unit Id | C16: 9 | D16: Numeric | E16: [Branded Value] | F16: Identifies the Vendor, set up by Portico at implementation Ex 88888888, 44444444 | G16: See List_BrandingValues_Portico for PAN | H16: 888888888
B17: Point of Service Condition Code | C17: 2 | D17: Numeric | F17: Constant value = 82 | G17: 82
B18: Account Id #1 | C18: 40 | F18: Combination of Length and Account Id. This is kind of From Account Ex : 12143000002=75 - Length (12) - Member ID (143000002= ) - Account ID (75)
B19: Account Id #1 - Length | C19: 2 | D19: Numeric | F19: 00(Length of AccountId) | G19: length of Account Id #1 - Account Id
B20: Account Id #1 - Account Id | C20: 38 | D20: AlphaNumeric | F20: Consists of Member ID and Account ID - Share account(DDA SDA) will be 2 digits 38 characters as account number (adding spaces if account number is less than 38 characters to make fixed length) | G20: See transformation rule AcctKeys/AcctId
B21: Account Id #2 | F21: Combination - consists of Length and Account Id - "To" Account | G21: 00bbbbbbbbbbbbbbbbbbbbbbbbbbbbbbbbbbbbbb
B22: Length | C22: 2 | D22: Numeric | F22: 00
B23: Account Id | C23: 38 | D23: AlphaNumeric | F23: Set value = Spaces
B24: Account 1 Pin | C24: 16 | D24: AlphaNumeric | E24: Not going to Validate the Pin | F24: Branded value(Set value = Spaces) | G24: bbbbbbbbbbbbbbbb
B25: Account 2 Pin (user entered pin) | C25: 16 | D25: AlphaNumeric | E25: Not going to Validate the Pin | F25: Branded value - Validating pin or not (Predetermined value and not auto generated)(Set value = Spaces) | G25: bbbbbbbbbbbbbbbb
B26: Card Acceptor Identification Code | F26: Combination - consists of Transaction Indicator , Spaces, Location Id and Spaces
B27: Transaction Indicator | C27: 6 | D27: AlphaNumeric | E27: [Branded Value] | F27: Set value = VBRANC (Identifies the network for the transaction) | G27: See List_BrandingValues_Portico for PAN | H27: VBRANC
B28: Space | C28: 1 | D28: AlphaNumeric | F28: b | G28: b
B29: Location Id | C29: 6 | D29: AlphaNumeric | E29: [Branded Value] | F29: SSIINT / SSIINP / SSIINV/ SSIINN(Refer screenshot on right)(per user), Can set Value to : SSIINT | G29: See List_BrandingValues_Portico for PAN | H29: SSIINT
B30: Request Count | C30: 2 | D30: AlphaNumeric | F30: ( Limiting the account inquiry records kind of MaxRecLimit when we do not send explicitly Account Id in request)any value which we have to limit or send spaces , Length = 2 | G30: bb
B31: Additional data | F31: Combination of Length , Network Id , Account Qualifier # 1 , Account Qualifier #2, Additional Criteria and Continuation Control
B32: Length | C32: 3 | D32: Numeric | F32: Set value = 039 | G32: 039
B33: Network Id | C33: 3 | D33: AlphaNumeric | F33: Set value = INT | G33: INT
B34: Account Qualifier #1 | C34: 3 | D34: AlphaNumeric | E34: Required at Portico - Confirm with all teams | F34: INQ – Account Inquiry It tells portico what kind of Account inquiry is performed. Fixed length account format or structured means having field and value fomat. Set value as "TAI" – Tokenized Account Inquiry (It will not be Fixed length format , it will always have fields and then value in the response, response formatting). Other Account Qualifier will be fixed Length such as INQ – Account Inquiry, EAI – Expanded Account Inquiry , XAI – Cross Account Inquiry | G34: DEM
B35: Account Qualifier #2 (Qualifies Process Code) | C35: 3 | D35: AlphaNumeric | E35: Required at Portico | F35: bbb – Account Inquiry Format EAI – Expanded Account Inquiry Format TAI – Tokenized Account Inquiry Format | G35: bbb
B36: Additional Criteria | C36: 20 | D36: AlphaNumeric | G36: bbbbbbbbbbbbbbbbbbbb
B37: Continuation Control | C37: 10 | D37: AlphaNumeric | F37: bbbbbbbbbb It will continue to the next set of records . Pagination . Portico will send how much data can fit in response , data varies in Tokenized response. Its not configured in Portico how many accounts it will return all depends on the data how much it return (Approx 40). Portico always send continuation if their is more data when we inquire All Accounts. . RecCtrlIn/Cursor is not provided or not present then Continuation Control will be having the blank spaces | G37: bbbbbbbbbb
B38: Card Acceptor Name/Location | C38: 40 | D38: AlphaNumeric | F38: Constant value = Account Inquiry (Portico does not care but for identification ESF can send Account Inquiry) | G38: Demographic Maintenance
B39: Date Transmitted | C39: 4 | D39: Numeric | F39: Portico Fomat : MMDD, ESF can set it to current date | G39: MMDD
B40: Time Transmitted | C40: 6 | D40: Numeric | F40: Portico Fomat : HHMMSS , ESF can set to current time | G40: HHMMSS
...

Sheet Parameter Configuration
A1: Open Issue | B1: Service Provider Schema
B2: Xpath | C2: Usage | D2: DataType | E2: Allowed Values | F2: Parameter Name

Sheet Compare
A1: XPATH | B1: Description | C1: Usage | D1: Type | E1: DataType | F1: Allowed Values | G1: AcctModRq | H1: AcctModRs
A2: OvrdAutoAckInd | B2: [FSVR]Override Autoacknowledgment. Used when the midleware is in charge of auto-acknowledgement of exceptions. | C2: Optional Choice | D2: Boolean_Type | E2: xsd:boolean | G2: X
A3: OvrdExceptionData | B3: [FSVR]Override Exception Data. Contains message exception that are to be overridden | C3: Optional Choice | D3: OvrdExceptionData_Type | E3: Aggregate | G3: X
A4: OvrdExceptionData/OverrideException | B4: [FSVR]Overrride Exception. | C4: Optional Repeating | D4: OverrideException_Type | E4: Aggregate | G4: X
A5: OvrdExceptionData/OverrideException/SubjectRole | B5: [FSVR]Subject Role. | C5: Optional | D5: SubjectRole_Type | E5: ExtendedEnum_Type | F5: Teller,Supervisor | G5: X
A6: OvrdExceptionData/OverrideException/SubjectIdent | B6: [FSVR]Subject Identifier. | C6: Optional | D6: Identifier_Type | E6: NC-36 | G6: X
A7: OvrdExceptionData/OverrideException/OvrdExceptionCode | B7: [IFXR]Overrride Exception Code.Identifies an exception code that is to be overridden. This would be the ServerStatusCode from the Status response. | C7: Optional | D7: OvrdExceptionCode_Type | E7: C-40 | G7: X
A8: OvrdExceptionData/OverrideException/OvrdElement | B8: [FSVR]Override Element. Information about the element that corresponds to the override exception code. | C8: Optional | D8: OvrdElement_Type | E8: Aggregate | G8: X
A9: OvrdExceptionData/OverrideException/OvrdElement/Path | B9: [IFXR]Path. Path indicates which EFX element is in being reported. It provides either the path of the element, or just the element name. If it provides the path, it must use XPath absolute notation with the starting node being the node of the message, and ending with the name of the element reported. | C9: Optional | D9: IfxPath_Type | E9: xsd:string | G9: X
A10: OvrdExceptionData/OverrideException/OvrdElement/ServerPath | B10: [FSVR]Server Path. Server Path indicates the Service Provider’s means of identifying the field that is in being reported (such as XPath, field ID, or field name). If this element is set, it must be returned in the ServerPath element of the OvrdExceptionData aggregate if the exception is being overridden | C10: Optional | D10: ServerPath_Type | E10: C-256 | G10: X
A11: OvrdExceptionData/OverrideException/OvrdElement/Value | B11: [IFXR]Path Value. Value string representation of the EFX data value of the element reported This field is intended to provide a human readable visual hint as to the value reported. It should not be provided for fields that cannot be represented as a string (i.e., binary data). | C11: Optional | D11: Value_Type | E11: C-256 | G11: X
A12: AcctKeys | B12: [IFXR]Account Identifier. Uniquely identifies an account held at a financial institution. | C12: Required | D12: AcctKeys_Type | E12: Aggregate | G12: X
A13: AcctKeys/AcctId | B13: [IFXR]Account Identifier. Uniquely identifies an account held at a financial institution. | C13: Required | D13: Identifier_Type | E13: NC-36 | G13: X
A14: AcctKeys/SubAcctId | B14: [FSVR]Sub Account Identifier. Also used as CostCenter for GLA Accounts. | C14: Optional | D14: Identifier_Type | E14: NC-36 | G14: X
A15: AcctKeys/AcctType | B15: [IFXR]Account Type. | C15: Optional | D15: AcctType_Type | E15: ExtendedEnum_Type | F15: CCA,RRA,LEAS,CDA,MLN,CLA,CRD,DDA,EQU,GLA,ILA,AdultCashISA,IRA,RET,EXT,JuniorCashISA,LIP,LOAN,LOC,CLOC,MLA,PBA,PORT,SDA,SDB,MMA,DDL | G15: X
A16: AcctKeys/CardKeys | B16: [IFXR]Card Keys. Used to identify the Card record. | C16: Required Choice | D16: CardKeys_Type | E16: Aggregate | G16: X
A17: AcctKeys/CardKeys/SvcIdent | B17: [IFXR]Service Identifier. Provide a unique reference to a service. | C17: Optional | D17: SvcIdent_Type | E17: Aggregate | G17: X
A18: AcctKeys/CardKeys/SvcIdent/SvcProviderName | B18: [IFXR]Service Provider Name . | C18: Optional | D18: URL_Type | E18: NC-1024 | G18: X
A19: AcctKeys/CardKeys/SvcIdent/SvcNbr | B19: [IFXR]Service Number. | C19: Optional | D19: Identifier_Type | E19: NC-36 | G19: X
A20: AcctKeys/CardKeys/SvcIdent/SvcName | B20: [IFXR]Service Name. | C20: Optional | D20: SvcName_Type | E20: C-32 | G20: X
A21: AcctKeys/CardKeys/ISOCode | B21: [FSVR]ISO Code. | C21: Optional | D21: OpenEnum_Type | E21: C-80 | G21: X
A22: AcctKeys/CardKeys/CardNum | B22: [IFXR]Card Number. | C22: Required Choice | D22: CardNum_Type | E22: NC-32 | G22: X
A23: AcctKeys/CardKeys/CardId | B23: [IFXR]Card Identifier. | C23: Required Choice | D23: Identifier_Type | E23: NC-36 | G23: X
A24: AcctKeys/CardKeys/CardSeqNum | B24: [IFXR]Card Sequence Number. | C24: Optional | D24: CardSeqNum_Type | E24: NC-3 | G24: X
A25: AcctKeys/CardKeys/CardIdent | B25: [FSVR]Card Identifier. | C25: Optional Choice | D25: CardIdent_Type | E25: Aggregate | G25: X
A26: AcctKeys/CardKeys/CardIdent/CardIdentType | B26: [FSVR]Card Identification Type. Valid values include: PORT | C26: Optional | D26: CardIdentType_Type | E26: ExtendedEnum_Type | F26: PORT | G26: X
A27: AcctKeys/CardKeys/CardIdent/CardIdentValue | B27: [FSVR]Card Identification Value. | C27: Optional | D27: CardIdentValue_Type | E27: NC-36 | G27: X
A28: AcctKeys/AcctIdent | B28: [IFXR]Account Identifier. Other account identifiers used as part of the account object key. | C28: Required Choice | D28: AcctIdent_Type | E28: Aggregate | G28: X
A29: AcctKeys/AcctIdent/AcctIdentType | B29: [IFXR]Account Identification Type. Valid values include: AcctNum, Port, AcctTypeCode. | C29: Optional | D29: AcctIdentType_Type | E29: ExtendedEnum_Type | F29: AcctNum,PORT,AccessId,PartyId,AliasAcct,AcctTypeCode,CLOC,DraftId,DraftId2,ACHId | G29: X
A30: AcctKeys/AcctIdent/AcctIdentValue | B30: [IFXR]Account Identification Value. | C30: Optional | D30: AcctIdentValue_Type | E30: NC-36 | G30: X
A31: AcctKeys/CurCode | B31: [IFXR]Currency Code. Use to identify the currency code of the account. | C31: Optional | D31: CurCode_Type | E31: Aggregate | G31: X
A32: AcctKeys/CurCode/CurCodeType | B32: [IFXR]Currency Code Type. | C32: Optional | D32: CurCodeType_Type | E32: ClosedEnum_Type | F32: ISO4217-Alpha,ISO4217-Numeric | G32: X
A33: AcctKeys/CurCode/CurCodeTypeEnumDesc | B33: [FSVR]Currency Code Type Enumeration Description. | C33: Optional | D33: EnumDesc_Type | E33: C-80 | G33: X
A34: AcctKeys/CurCode/CurCodeValue | B34: [IFXR]Currency Code Value. | C34: Required | D34: OpenEnum_Type | E34: C-80 | G34: X
A35: AcctKeys/FIIdentType | B35: [IFXR]Financial Institution Identification Type. | C35: Optional | D35: FIIdentType_Type | E35: ExtendedEnum_Type | F35: ABA,RoutingNum | G35: X
A36: AcctKeys/FIIdent | B36: [IFXR]Financial Institution Identification. | C36: Optional | D36: FIIdent_Type | E36: NC-34 | G36: X
A37: AcctKeys/BranchIdent | B37: [IFXR]Branch Identifier. | C37: Optional | D37: BranchIdent_Type | E37: NC-22 | G37: X
A38: DepositAcctInfo | B38: [FSVR]Deposit Account Information. The DepositAcctInfo aggregate contains the details of a Deposit Account. | C38: Required Choice | D38: DepositAcctInfo_Type | E38: Aggregate | G38: X
A39: DepositAcctInfo/Brand | B39: [FSVR]Brand. | C39: Optional | D39: OpenEnum_Type | E39: C-80 | G39: X
A40: DepositAcctInfo/GoodThruDt | B40: [FSVR]Good Thru Date. Indicates the current processing date of the system. | C40: Optional | D40: Date_Type | E40: xsd:date | G40: X
...

Sheet Change Log
A1: Date: | B1: 45975 | C1: Macro Event: | D1: New mapping sheet schema version 9.0.20251027 | E1: Macro Version: | F1: 4.2018082
A2: EFX Xpath | B2: Action | C2: Column | D2: Old Value | E2: New Value | G2: Implemented
A3: OvrdAutoAckInd | B3: Add | D3: This was added to the OrvrdException Mapping tab
A4: Rows Added: 4623
A5: Rows Deleted: 0
A6: Differences: 2

Sheet Backup
B13: RecCtrlOut/Cursor | C13: Matched Record Count. Next Record Pointer Included in the response only if additional records are available. | D13: Optional | E13: C-250
